Workbook

Sheet Cover Page
O3: #033E34 | P3: #0000FF
O4: #C9F223 | P4: #E2FEF9
B5: Company Name | E5: Caterpillar Inc. (CAT)
E14: Table of Contents
E16: P&L | L16: 1
E17: Balance Sheet | L17: 2
E18: Cash Flow | L18: 3
E19: DCF Model | L19: 4
E20: Comps Table | L20: 5
E21: Output Charts | L21: 6
E22: Ratio Analysis | L22: 7
E23: Assumptions | L23: 8
E24: Input Data | L24: 9

Sheet P&L
B2: Income Statement
B3: ='Cover Page'!E5&" | "&TEXT(TODAY(),"mmmm d, yyyy") -> Caterpillar Inc. (CAT) | February 11, 2026
B5: =+Assumptions!$D$11 -> USD' millions | S5: Scenario | T5: BASE
B7: Selected Scenario/Case
B8: Days Per Period | G8: 365 | H8: 365 | I8: 365 | J8: 365 | K8: 365 | L8: 365 | M8: 365 | N8: 365 | O8: 365 | P8: 365 | Q8: 365 | R8: 365
B10: Income Statement Drivers
B11: =+Assumptions!B17 -> Revenue growth (% change) | L11: =OFFSET(Assumptions!G17,MATCH('P&L'!$T$5,Assumptions!$B$18:$B$20,0),0) -> 0.07 | M11: =OFFSET(Assumptions!H17,MATCH('P&L'!$T$5,Assumptions!$B$18:$B$20,0),0) -> 0.07 | N11: =OFFSET(Assumptions!I17,MATCH('P&L'!$T$5,Assumptions!$B$18:$B$20,0),0) -> 0.05 | O11: =OFFSET(Assumptions!J17,MATCH('P&L'!$T$5,Assumptions!$B$18:$B$20,0),0) -> 0.05 | P11: =OFFSET(Assumptions!K17,MATCH('P&L'!$T$5,Assumptions!$B$18:$B$20,0),0) -> 0.05 | Q11: =OFFSET(Assumptions!L17,MATCH('P&L'!$T$5,Assumptions!$B$18:$B$20,0),0) -> 0.05 | R11: =OFFSET(Assumptions!M17,MATCH('P&L'!$T$5,Assumptions!$B$18:$B$20,0),0) -> 0.05
B12: =+Assumptions!B22 -> Cost of sales (% of revenue) | L12: =OFFSET(Assumptions!G22,MATCH('P&L'!$T$5,Assumptions!$B$23:$B$25,0),0) -> 0.66 | M12: =OFFSET(Assumptions!H22,MATCH('P&L'!$T$5,Assumptions!$B$23:$B$25,0),0) -> 0.66 | N12: =OFFSET(Assumptions!I22,MATCH('P&L'!$T$5,Assumptions!$B$23:$B$25,0),0) -> 0.63 | O12: =OFFSET(Assumptions!J22,MATCH('P&L'!$T$5,Assumptions!$B$23:$B$25,0),0) -> 0.63 | P12: =OFFSET(Assumptions!K22,MATCH('P&L'!$T$5,Assumptions!$B$23:$B$25,0),0) -> 0.63 | Q12: =OFFSET(Assumptions!L22,MATCH('P&L'!$T$5,Assumptions!$B$23:$B$25,0),0) -> 0.63 | R12: =OFFSET(Assumptions!M22,MATCH('P&L'!$T$5,Assumptions!$B$23:$B$25,0),0) -> 0.63
B13: =+Assumptions!B27 -> Sales, general and administrative (% of revenue) | L13: =OFFSET(Assumptions!G27,MATCH('P&L'!$T$5,Assumptions!$B$28:$B$30,0),0) -> 0.0635 | M13: =OFFSET(Assumptions!H27,MATCH('P&L'!$T$5,Assumptions!$B$28:$B$30,0),0) -> 0.0635 | N13: =OFFSET(Assumptions!I27,MATCH('P&L'!$T$5,Assumptions!$B$28:$B$30,0),0) -> 0.0645 | O13: =OFFSET(Assumptions!J27,MATCH('P&L'!$T$5,Assumptions!$B$28:$B$30,0),0) -> 0.0645 | P13: =OFFSET(Assumptions!K27,MATCH('P&L'!$T$5,Assumptions!$B$28:$B$30,0),0) -> 0.0645 | Q13: =OFFSET(Assumptions!L27,MATCH('P&L'!$T$5,Assumptions!$B$28:$B$30,0),0) -> 0.0645 | R13: =OFFSET(Assumptions!M27,MATCH('P&L'!$T$5,Assumptions!$B$28:$B$30,0),0) -> 0.0645
B14: =+Assumptions!B32 -> Research and development (% of revenue) | L14: =OFFSET(Assumptions!G32,MATCH('P&L'!$T$5,Assumptions!$B$33:$B$35,0),0) -> 0.033 | M14: =OFFSET(Assumptions!H32,MATCH('P&L'!$T$5,Assumptions!$B$33:$B$35,0),0) -> 0.033 | N14: =OFFSET(Assumptions!I32,MATCH('P&L'!$T$5,Assumptions!$B$33:$B$35,0),0) -> 0.032 | O14: =OFFSET(Assumptions!J32,MATCH('P&L'!$T$5,Assumptions!$B$33:$B$35,0),0) -> 0.032 | P14: =OFFSET(Assumptions!K32,MATCH('P&L'!$T$5,Assumptions!$B$33:$B$35,0),0) -> 0.032 | Q14: =OFFSET(Assumptions!L32,MATCH('P&L'!$T$5,Assumptions!$B$33:$B$35,0),0) -> 0.032 | R14: =OFFSET(Assumptions!M32,MATCH('P&L'!$T$5,Assumptions!$B$33:$B$35,0),0) -> 0.032
B15: Other operating expenses (% of revenue) | L15: =OFFSET(Assumptions!G37,MATCH('P&L'!$T$5,Assumptions!$B$38:$B$40,0),0) -> 0.038 | M15: =OFFSET(Assumptions!H37,MATCH('P&L'!$T$5,Assumptions!$B$38:$B$40,0),0) -> 0.038 | N15: =OFFSET(Assumptions!I37,MATCH('P&L'!$T$5,Assumptions!$B$38:$B$40,0),0) -> 0.04 | O15: =OFFSET(Assumptions!J37,MATCH('P&L'!$T$5,Assumptions!$B$38:$B$40,0),0) -> 0.04 | P15: =OFFSET(Assumptions!K37,MATCH('P&L'!$T$5,Assumptions!$B$38:$B$40,0),0) -> 0.04 | Q15: =OFFSET(Assumptions!L37,MATCH('P&L'!$T$5,Assumptions!$B$38:$B$40,0),0) -> 0.04 | R15: =OFFSET(Assumptions!M37,MATCH('P&L'!$T$5,Assumptions!$B$38:$B$40,0),0) -> 0.04
B16: =+Assumptions!B42 -> D&A (% of Beginning PPE) | L16: =OFFSET(Assumptions!G42,MATCH('P&L'!$T$5,Assumptions!$B$43:$B$45,0),0) -> 0.175 | M16: =OFFSET(Assumptions!H42,MATCH('P&L'!$T$5,Assumptions!$B$43:$B$45,0),0) -> 0.175 | N16: =OFFSET(Assumptions!I42,MATCH('P&L'!$T$5,Assumptions!$B$43:$B$45,0),0) -> 0.165 | O16: =OFFSET(Assumptions!J42,MATCH('P&L'!$T$5,Assumptions!$B$43:$B$45,0),0) -> 0.165 | P16: =OFFSET(Assumptions!K42,MATCH('P&L'!$T$5,Assumptions!$B$43:$B$45,0),0) -> 0.165 | Q16: =OFFSET(Assumptions!L42,MATCH('P&L'!$T$5,Assumptions!$B$43:$B$45,0),0) -> 0.165 | R16: =OFFSET(Assumptions!M42,MATCH('P&L'!$T$5,Assumptions!$B$43:$B$45,0),0) -> 0.165
B17: =+Assumptions!B47 -> Tax rate (% of Earnings Before Tax) | L17: =OFFSET(Assumptions!G47,MATCH('P&L'!$T$5,Assumptions!$B$48:$B$50,0),0) -> 0.21 | M17: =OFFSET(Assumptions!H47,MATCH('P&L'!$T$5,Assumptions!$B$48:$B$50,0),0) -> 0.21 | N17: =OFFSET(Assumptions!I47,MATCH('P&L'!$T$5,Assumptions!$B$48:$B$50,0),0) -> 0.21 | O17: =OFFSET(Assumptions!J47,MATCH('P&L'!$T$5,Assumptions!$B$48:$B$50,0),0) -> 0.21 | P17: =OFFSET(Assumptions!K47,MATCH('P&L'!$T$5,Assumptions!$B$48:$B$50,0),0) -> 0.21 | Q17: =OFFSET(Assumptions!L47,MATCH('P&L'!$T$5,Assumptions!$B$48:$B$50,0),0) -> 0.21 | R17: =OFFSET(Assumptions!M47,MATCH('P&L'!$T$5,Assumptions!$B$48:$B$50,0),0) -> 0.21
B19: Income Statement
B21: Year End | G21: =+DATE(YEAR(H21)-1,MONTH(H21),DAY(H21)) -> 44561 | H21: =+DATE(YEAR(I21)-1,MONTH(I21),DAY(I21)) -> 44926 | I21: =+DATE(YEAR(J21)-1,MONTH(J21),DAY(J21)) -> 45291 | J21: =+DATE(YEAR(K21)-1,MONTH(K21),DAY(K21)) -> 45657 | K21: =+DATE(YEAR(Assumptions!$D$10)-1,MONTH(Assumptions!$D$10),DAY(Assumptions!$D$10)) -> 46022 | L21: =+DATE(YEAR(K21)+1,MONTH(K21),DAY(K21)) -> 46387 | M21: =+DATE(YEAR(L21)+1,MONTH(L21),DAY(L21)) -> 46752 | N21: =+DATE(YEAR(M21)+1,MONTH(M21),DAY(M21)) -> 47118 | O21: =+DATE(YEAR(N21)+1,MONTH(N21),DAY(N21)) -> 47483 | P21: =+DATE(YEAR(O21)+1,MONTH(O21),DAY(O21)) -> 47848 | Q21: =+DATE(YEAR(P21)+1,MONTH(P21),DAY(P21)) -> 48213 | R21: =+DATE(YEAR(Q21)+1,MONTH(Q21),DAY(Q21)) -> 48579
G22: Actual | H22: Actual | I22: Actual | J22: Actual | K22: Actual | L22: Fcst | M22: Fcst | N22: Fcst | O22: Fcst | P22: Fcst | Q22: Fcst | R22: Fcst
B24: Revenue | G24: =+'Input Data'!E8 -> 50971 | H24: =+'Input Data'!F8 -> 59427 | I24: =+'Input Data'!G8 -> 67060 | J24: =+'Input Data'!H8 -> 64809 | K24: =+'Input Data'!I8 -> 67589 | L24: =+K$24*(1+L$11) -> 72320.23 | M24: =+L$24*(1+M$11) -> 77382.646 | N24: =+M$24*(1+N$11) -> 81251.778 | O24: =+N$24*(1+O$11) -> 85314.367 | P24: =+O$24*(1+P$11) -> 89580.086 | Q24: =+P$24*(1+Q$11) -> 94059.09 | R24: =+Q$24*(1+R$11) -> 98762.044
B25: Cost of sales | G25: =+'Input Data'!E11*-1 -> -35513 | H25: =+'Input Data'!F11*-1 -> -41350 | I25: =+'Input Data'!G11*-1 -> -42767 | J25: =+'Input Data'!H11*-1 -> -40199 | K25: =+'Input Data'!I11*-1 -> -44752 | L25: =+L24*L$12*-1 -> -47731.352 | M25: =+M24*M$12*-1 -> -51072.546 | N25: =+N24*N$12*-1 -> -51188.62 | O25: =+O24*O$12*-1 -> -53748.051 | P25: =+P24*P$12*-1 -> -56435.454 | Q25: =+Q24*Q$12*-1 -> -59257.227 | R25: =+R24*R$12*-1 -> -62220.088
B26: Gross profit | G26: =+SUM(G24:G25) -> 15458 | H26: =+SUM(H24:H25) -> 18077 | I26: =+SUM(I24:I25) -> 24293 | J26: =+SUM(J24:J25) -> 24610 | K26: =+SUM(K24:K25) -> 22837 | L26: =+SUM(L24:L25) -> 24588.878 | M26: =+SUM(M24:M25) -> 26310.1 | N26: =+SUM(N24:N25) -> 30063.158 | ... R26: =+SUM(R24:R25) -> 36541.956
B27: Gross profit margin | G27: =+G$26/G$24 -> 0.30327049 | H27: =+H$26/H$24 -> 0.30418833 | I27: =+I$26/I$24 -> 0.36225768 | J27: =+J$26/J$24 -> 0.37973121 | K27: =+K$26/K$24 -> 0.33788042 | L27: =+L$26/L$24 -> 0.34 | M27: =+M$26/M$24 -> 0.34 | N27: =+N$26/N$24 -> 0.37 | ... R27: =+R$26/R$24 -> 0.37
B28: Operating expenses | G28: =+SUM(G29:G32) -> -8580 | H28: =+SUM(H29:H32) -> -10173 | I28: =+SUM(I29:I32) -> -11327 | J28: =+SUM(J29:J32) -> -11538 | K28: =+SUM(K29:K32) -> -11686 | L28: =+SUM(L29:L32) -> -12376.571 | M28: =+SUM(M29:M32) -> -13401.901 | N28: =+SUM(N29:N32) -> -14249.469 | ... R28: =+SUM(R29:R32) -> -17393.972
B29: Sales, general and administrative | G29: =+'Input Data'!E13*-1 -> -3013 | H29: =+'Input Data'!F13*-1 -> -3432 | I29: =+'Input Data'!G13*-1 -> -4227 | J29: =+'Input Data'!H13*-1 -> -4514 | K29: =+'Input Data'!I13*-1 -> -4723 | L29: =+L$24*L$13*-1 -> -4592.3346 | M29: =+M$24*M$13*-1 -> -4913.798 | N29: =+N$24*N$13*-1 -> -5240.7397 | O29: =+O$24*O$13*-1 -> -5502.7767 | P29: =+P$24*P$13*-1 -> -5777.9155 | Q29: =+Q$24*Q$13*-1 -> -6066.8113 | R29: =+R$24*R$13*-1 -> -6370.1519
B30: Research and development | G30: =+'Input Data'!E15*-1 -> -1686 | H30: =+'Input Data'!F15*-1 -> -1814 | I30: =+'Input Data'!G15*-1 -> -2108 | J30: =+'Input Data'!H15*-1 -> -2107 | K30: =+'Input Data'!I15*-1 -> -2148 | L30: =+L$24*L$14*-1 -> -2386.5676 | M30: =+M$24*M$14*-1 -> -2553.6273 | N30: =+N$24*N$14*-1 -> -2600.0569 | O30: =+O$24*O$14*-1 -> -2730.0598 | P30: =+P$24*P$14*-1 -> -2866.5627 | Q30: =+Q$24*Q$14*-1 -> -3009.8909 | R30: =+R$24*R$14*-1 -> -3160.3854
B31: Other operating expenses | G31: =+SUM('Input Data'!E16:E18)*-1 -> -1529 | H31: =+SUM('Input Data'!F16:F18)*-1 -> -2708 | I31: =+SUM('Input Data'!G16:G18)*-1 -> -2848 | J31: =+SUM('Input Data'!H16:H18)*-1 -> -2764 | K31: =+SUM('Input Data'!I16:I18)*-1 -> -2553 | L31: =+L$24*L$15*-1 -> -2748.1687 | M31: =+M$24*M$15*-1 -> -2940.5406 | N31: =+N$24*N$15*-1 -> -3250.0711 | O31: =+O$24*O$15*-1 -> -3412.5747 | P31: =+P$24*P$15*-1 -> -3583.2034 | Q31: =+Q$24*Q$15*-1 -> -3762.3636 | R31: =+R$24*R$15*-1 -> -3950.4818
B32: D&A | G32: =+'Input Data'!E14*-1 -> -2352 | H32: =+'Input Data'!F14*-1 -> -2219 | I32: =+'Input Data'!G14*-1 -> -2144 | J32: =+'Input Data'!H14*-1 -> -2153 | K32: =+'Input Data'!I14*-1 -> -2262 | L32: =+'Balance Sheet '!L$47 -> -2649.5 | M32: =+'Balance Sheet '!M$47 -> -2993.935 | N32: =+'Balance Sheet '!N$47 -> -3158.6014 | O32: =+'Balance Sheet '!O$47 -> -3332.3245 | P32: =+'Balance Sheet '!P$47 -> -3515.6024 | Q32: =+'Balance Sheet '!Q$47 -> -3708.9605 | R32: =+'Balance Sheet '!R$47 -> -3912.9533
B33: Other income/(expenses) | G33: =+'Input Data'!E24 -> 1814 | H33: =+'Input Data'!F24 -> 1291 | I33: =+'Input Data'!G24 -> 595 | J33: =+'Input Data'!H24 -> 813 | K33: =+'Input Data'!I24 -> 892
B34: EBIT | G34: =+G$26+G$28+G33 -> 8692 | H34: =+H$26+H$28+H33 -> 9195 | I34: =+I$26+I$28+I33 -> 13561 | J34: =+J$26+J$28+J33 -> 13885 | K34: =+K$26+K$28+K33 -> 12043 | L34: =+L$26+L$28+L33 -> 12212.307 | M34: =+M$26+M$28+M33 -> 12908.199 | N34: =+N$26+N$28+N33 -> 15813.689 | ... R34: =+R$26+R$28+R33 -> 19147.984
B35: Interest expense | G35: =+'Input Data'!E23*-1 -> -488 | H35: =+'Input Data'!F23*-1 -> -443 | I35: =+'Input Data'!G23*-1 -> -511 | J35: =+'Input Data'!H23*-1 -> -512 | K35: =+'Input Data'!I23*-1 -> -502 | L35: =+'Balance Sheet '!G$80 -> -3033.1 | M35: =+'Balance Sheet '!H$80 -> -2863.5437 | N35: =+'Balance Sheet '!I$80 -> -2682.1184 | O35: =+'Balance Sheet '!J$80 -> -2487.9934 | P35: =+'Balance Sheet '!K$80 -> -2280.2796 | Q35: =+'Balance Sheet '!L$80 -> -2058.0258 | R35: =+'Balance Sheet '!M$80 -> -1820.2143
B36: Earnings before tax | G36: =+SUM(G34:G35) -> 8204 | H36: =+SUM(H34:H35) -> 8752 | I36: =+SUM(I34:I35) -> 13050 | J36: =+SUM(J34:J35) -> 13373 | K36: =+SUM(K34:K35) -> 11541 | L36: =+SUM(L34:L35) -> 9179.2073 | M36: =+SUM(M34:M35) -> 10044.655 | N36: =+SUM(N34:N35) -> 13131.57 | ... R36: =+SUM(R34:R35) -> 17327.77
B37: Tax | G37: =+'Input Data'!E27*-1 -> -1742 | H37: =+'Input Data'!F27*-1 -> -2067 | I37: =+'Input Data'!G27*-1 -> -2781 | J37: =+'Input Data'!H27*-1 -> -2629 | K37: =+'Input Data'!I27*-1 -> -2768 | L37: =L36*L$17*-1 -> -1927.6335 | M37: =M36*M$17*-1 -> -2109.3776 | N37: =N36*N$17*-1 -> -2757.6298 | O37: =O36*O$17*-1 -> -2961.1232 | P37: =P36*P$17*-1 -> -3175.4243 | Q37: =Q36*Q$17*-1 -> -3401.1203 | R37: =R36*R$17*-1 -> -3638.8316
B38: Net earnings/(losses) | G38: =+SUM(G36,G37) -> 6462 | H38: =+SUM(H36,H37) -> 6685 | I38: =+SUM(I36,I37) -> 10269 | J38: =+SUM(J36,J37) -> 10744 | K38: =+SUM(K36,K37) -> 8773 | L38: =+SUM(L36,L37) -> 7251.5737 | M38: =+SUM(M36,M37) -> 7935.2775 | N38: =+SUM(N36,N37) -> 10373.941 | ... R38: =+SUM(R36,R37) -> 13688.938
B41: EBITDA Normalizatiion
B42: EBIT | G42: =+G$34 -> 8692 | H42: =+H$34 -> 9195 | I42: =+I$34 -> 13561 | J42: =+J$34 -> 13885 | K42: =+K$34 -> 12043 | L42: =+L34 -> 12212.307 | M42: =+M34 -> 12908.199 | N42: =+N34 -> 15813.689 | O42: =+O34 -> 16588.58 | P42: =+P34 -> 17401.348 | Q42: =+Q34 -> 18253.837 | R42: =+R34 -> 19147.984
B43: Plus: D&A | G43: =+G$32*-1 -> 2352 | H43: =+H$32*-1 -> 2219 | I43: =+I$32*-1 -> 2144 | J43: =+J$32*-1 -> 2153 | K43: =+K$32*-1 -> 2262 | L43: =+L$32*-1 -> 2649.5 | M43: =+M$32*-1 -> 2993.935 | N43: =+N$32*-1 -> 3158.6014 | ... R43: =+R$32*-1 -> 3912.9533
B44: Plus: Adjustments | G44: =+G33*-1 -> -1814 | H44: =+H33*-1 -> -1291 | I44: =+I33*-1 -> -595 | J44: =+J33*-1 -> -813 | K44: =+K33*-1 -> -892
B45: EBITDA (normalized) | G45: =+SUM(G42:G44) -> 9230 | H45: =+SUM(H42:H44) -> 10123 | I45: =+SUM(I42:I44) -> 15110 | J45: =+SUM(J42:J44) -> 15225 | K45: =+SUM(K42:K44) -> 13413 | L45: =+SUM(L42:L44) -> 14861.807 | M45: =+SUM(M42:M44) -> 15902.134 | N45: =+SUM(N42:N44) -> 18972.29 | ... R45: =+SUM(R42:R44) -> 23060.937
B46: EBITDA margin | G46: =+G$45/G$24 -> 0.18108336 | H46: =+H$45/H$24 -> 0.17034345 | I46: =+I$45/I$24 -> 0.22532061 | J46: =+J$45/J$24 -> 0.23492108 | K46: =+K$45/K$24 -> 0.19844945 | L46: =+L$45/L$24 -> 0.2055 | M46: =+M$45/M$24 -> 0.2055 | N46: =+N$45/N$24 -> 0.2335 | ... R46: =+R$45/R$24 -> 0.2335
B48: Common-size Analysis
B50: Cost of sales | G50: =+G25/G24*-1 -> 0.69672951 | H50: =+H25/H24*-1 -> 0.69581167 | I50: =+I25/I24*-1 -> 0.63774232 | J50: =+J25/J24*-1 -> 0.62026879 | K50: =+K25/K24*-1 -> 0.66211958
B51: Gross profit | G51: =+G26/G24 -> 0.30327049 | H51: =+H26/H24 -> 0.30418833 | I51: =+I26/I24 -> 0.36225768 | J51: =+J26/J24 -> 0.37973121 | K51: =+K26/K24 -> 0.33788042
...

Sheet Balance Sheet 
B2: Balance Sheet
B3: ='Cover Page'!E5&" | "&TEXT(TODAY(),"mmmm d, yyyy") -> Caterpillar Inc. (CAT) | February 11, 2026
B5: =+Assumptions!$D$11 -> USD' millions | S5: Scenario | T5: =+'P&L'!$T$5 -> BASE
B7: Selected Scenario/Case
B8: Days Per Period | G8: 365 | H8: 365 | I8: 365 | J8: 365 | K8: 365 | L8: 365 | M8: 365 | N8: 365 | O8: 365 | P8: 365 | Q8: 365 | R8: 365
B10: Balance Sheet Drivers
B11: Trade receivable (days) | L11: =OFFSET(Assumptions!G53,MATCH('P&L'!$T$5,Assumptions!$B$54:$B$56,0),0) -> 106 | M11: =OFFSET(Assumptions!H53,MATCH('P&L'!$T$5,Assumptions!$B$54:$B$56,0),0) -> 106 | N11: =OFFSET(Assumptions!I53,MATCH('P&L'!$T$5,Assumptions!$B$54:$B$56,0),0) -> 106 | O11: =OFFSET(Assumptions!J53,MATCH('P&L'!$T$5,Assumptions!$B$54:$B$56,0),0) -> 106 | P11: =OFFSET(Assumptions!K53,MATCH('P&L'!$T$5,Assumptions!$B$54:$B$56,0),0) -> 106 | Q11: =OFFSET(Assumptions!L53,MATCH('P&L'!$T$5,Assumptions!$B$54:$B$56,0),0) -> 106 | R11: =OFFSET(Assumptions!M53,MATCH('P&L'!$T$5,Assumptions!$B$54:$B$56,0),0) -> 106
B12: Inventory (days) | L12: =OFFSET(Assumptions!G58,MATCH('P&L'!$T$5,Assumptions!$B$59:$B$61,0),0) -> 142 | M12: =OFFSET(Assumptions!H58,MATCH('P&L'!$T$5,Assumptions!$B$59:$B$61,0),0) -> 142 | N12: =OFFSET(Assumptions!I58,MATCH('P&L'!$T$5,Assumptions!$B$59:$B$61,0),0) -> 142 | O12: =OFFSET(Assumptions!J58,MATCH('P&L'!$T$5,Assumptions!$B$59:$B$61,0),0) -> 142 | P12: =OFFSET(Assumptions!K58,MATCH('P&L'!$T$5,Assumptions!$B$59:$B$61,0),0) -> 142 | Q12: =OFFSET(Assumptions!L58,MATCH('P&L'!$T$5,Assumptions!$B$59:$B$61,0),0) -> 142 | R12: =OFFSET(Assumptions!M58,MATCH('P&L'!$T$5,Assumptions!$B$59:$B$61,0),0) -> 142
B13: Trade payable (days) | L13: =OFFSET(Assumptions!G63,MATCH('P&L'!$T$5,Assumptions!$B$64:$B$66,0),0) -> 71 | M13: =OFFSET(Assumptions!H63,MATCH('P&L'!$T$5,Assumptions!$B$64:$B$66,0),0) -> 71 | N13: =OFFSET(Assumptions!I63,MATCH('P&L'!$T$5,Assumptions!$B$64:$B$66,0),0) -> 71 | O13: =OFFSET(Assumptions!J63,MATCH('P&L'!$T$5,Assumptions!$B$64:$B$66,0),0) -> 71 | P13: =OFFSET(Assumptions!K63,MATCH('P&L'!$T$5,Assumptions!$B$64:$B$66,0),0) -> 71 | Q13: =OFFSET(Assumptions!L63,MATCH('P&L'!$T$5,Assumptions!$B$64:$B$66,0),0) -> 71 | R13: =OFFSET(Assumptions!M63,MATCH('P&L'!$T$5,Assumptions!$B$64:$B$66,0),0) -> 71
B14: Capex | L14: =OFFSET(Assumptions!G68,MATCH($T$5,Assumptions!$B$69:$B$71,0),0) -> 0.305 | M14: =OFFSET(Assumptions!H68,MATCH($T$5,Assumptions!$B$69:$B$71,0),0) -> 0.23 | N14: =OFFSET(Assumptions!I68,MATCH($T$5,Assumptions!$B$69:$B$71,0),0) -> 0.23 | O14: =OFFSET(Assumptions!J68,MATCH($T$5,Assumptions!$B$69:$B$71,0),0) -> 0.23 | P14: =OFFSET(Assumptions!K68,MATCH($T$5,Assumptions!$B$69:$B$71,0),0) -> 0.23 | Q14: =OFFSET(Assumptions!L68,MATCH($T$5,Assumptions!$B$69:$B$71,0),0) -> 0.23 | R14: =OFFSET(Assumptions!M68,MATCH($T$5,Assumptions!$B$69:$B$71,0),0) -> 0.23
B16: Balance Sheet
B18: Year End | G18: =+DATE(YEAR(H18)-1,MONTH(H18),DAY(H18)) -> 44561 | H18: =+DATE(YEAR(I18)-1,MONTH(I18),DAY(I18)) -> 44926 | I18: =+DATE(YEAR(J18)-1,MONTH(J18),DAY(J18)) -> 45291 | J18: =+DATE(YEAR(K18)-1,MONTH(K18),DAY(K18)) -> 45657 | K18: =+DATE(YEAR(Assumptions!$D$10)-1,MONTH(Assumptions!$D$10),DAY(Assumptions!$D$10)) -> 46022 | L18: =+DATE(YEAR(K18)+1,MONTH(K18),DAY(K18)) -> 46387 | M18: =+DATE(YEAR(L18)+1,MONTH(L18),DAY(L18)) -> 46752 | N18: =+DATE(YEAR(M18)+1,MONTH(M18),DAY(M18)) -> 47118 | O18: =+DATE(YEAR(N18)+1,MONTH(N18),DAY(N18)) -> 47483 | P18: =+DATE(YEAR(O18)+1,MONTH(O18),DAY(O18)) -> 47848 | Q18: =+DATE(YEAR(P18)+1,MONTH(P18),DAY(P18)) -> 48213 | R18: =+DATE(YEAR(Q18)+1,MONTH(Q18),DAY(Q18)) -> 48579
G19: Actual | H19: Actual | I19: Actual | J19: Actual | K19: Actual | L19: Fcst | M19: Fcst | N19: Fcst | O19: Fcst | P19: Fcst | Q19: Fcst | R19: Fcst
B20: ASSETS
B21: PPE | G21: =+'Input Data'!E42 -> 12090 | H21: =+'Input Data'!F42 -> 12028 | I21: =+'Input Data'!G42 -> 12680 | J21: =+'Input Data'!H42 -> 13361 | K21: =+'Input Data'!I42 -> 15140 | L21: =+L$49 -> 17108.2 | M21: =+M$49 -> 18049.151 | N21: =+N$49 -> 19041.854 | O21: =+O$49 -> 20089.156 | P21: =+P$49 -> 21194.06 | Q21: =+Q$49 -> 22359.733 | R21: =+R$49 -> 23589.519
B22: Goodwill and intagible assets | G22: =+'Input Data'!E44 -> 7366 | H22: =+'Input Data'!F44 -> 6046 | I22: =+'Input Data'!G44 -> 5872 | J22: =+'Input Data'!H44 -> 5640 | K22: =+'Input Data'!I44 -> 5562 | L22: =+K22 -> 5562 | M22: =+L22 -> 5562 | N22: =+M22 -> 5562 | O22: =+N22 -> 5562 | P22: =+O22 -> 5562 | Q22: =+P22 -> 5562 | R22: =+Q22 -> 5562 | S22: *
B23: Other non current assets | G23: =+'Input Data'!E43+'Input Data'!E45 -> 19882 | H23: =+'Input Data'!F43+'Input Data'!F45 -> 20084 | I23: =+'Input Data'!G43+'Input Data'!G45 -> 21975 | J23: =+'Input Data'!H43+'Input Data'!H45 -> 23081 | K23: =+'Input Data'!I43+'Input Data'!I45 -> 25398 | L23: =+K23 -> 25398 | M23: =+L23 -> 25398 | N23: =+M23 -> 25398 | O23: =+N23 -> 25398 | P23: =+O23 -> 25398 | Q23: =+P23 -> 25398 | R23: =+Q23 -> 25398
B24: Inventory | G24: =+'Input Data'!E39 -> 14038 | H24: =+'Input Data'!F39 -> 16270 | I24: =+'Input Data'!G39 -> 16565 | J24: =+'Input Data'!H39 -> 16827 | K24: =+'Input Data'!I39 -> 18135 | L24: =+L$61 -> 18569.457 | M24: =+M$61 -> 19869.319 | N24: =+N$61 -> 19914.477 | O24: =+O$61 -> 20910.201 | P24: =+P$61 -> 21955.711 | Q24: =+Q$61 -> 23053.496 | R24: =+R$61 -> 24206.171
B25: Trade and other receivables | G25: =+SUM('Input Data'!E37:E38) -> 17375 | H25: =+SUM('Input Data'!F37:F38) -> 17869 | I25: =+SUM('Input Data'!G37:G38) -> 18820 | J25: =+SUM('Input Data'!H37:H38) -> 18847 | K25: =+SUM('Input Data'!I37:I38) -> 21569 | L25: =+L$60 -> 21002.587 | M25: =+M$60 -> 22472.768 | N25: =+N$60 -> 23596.407 | O25: =+O$60 -> 24776.227 | P25: =+P$60 -> 26015.039 | Q25: =+Q$60 -> 27315.791 | R25: =+R$60 -> 28681.58
B26: Cash & cash equivalents | G26: =+'Input Data'!E36 -> 9254 | H26: =+'Input Data'!F36 -> 7004 | I26: =+'Input Data'!G36 -> 6978 | J26: =+'Input Data'!H36 -> 6889 | K26: =+'Input Data'!I36 -> 9980 | L26: =+'Cash Flow'!L$34 -> 14158.739 | M26: =+'Cash Flow'!M$34 -> 19040.888 | N26: =+'Cash Flow'!N$34 -> 24593.009 | O26: =+'Cash Flow'!O$34 -> 32031.596 | P26: =+'Cash Flow'!P$34 -> 40026.736 | Q26: =+'Cash Flow'!Q$34 -> 48604.373 | R26: =+'Cash Flow'!R$34 -> 57791.63
B27: Other current assets | G27: =+'Input Data'!E40 -> 2788 | H27: =+'Input Data'!F40 -> 2642 | I27: =+'Input Data'!G40 -> 4586 | J27: =+'Input Data'!H40 -> 3119 | K27: =+'Input Data'!I40 -> 2801 | L27: =+K27 -> 2801 | M27: =+L27 -> 2801 | N27: =+M27 -> 2801 | O27: =+N27 -> 2801 | P27: =+O27 -> 2801 | Q27: =+P27 -> 2801 | R27: =+Q27 -> 2801 | S27: *
B28: TOTAL ASSETS | G28: =+SUM(G21:G23,G24:G27) -> 82793 | H28: =+SUM(H21:H23,H24:H27) -> 81943 | I28: =+SUM(I21:I23,I24:I27) -> 87476 | J28: =+SUM(J21:J23,J24:J27) -> 87764 | K28: =+SUM(K21:K23,K24:K27) -> 98585 | L28: =+SUM(L21:L23,L24:L27) -> 104599.98 | M28: =+SUM(M21:M23,M24:M27) -> 113193.13 | N28: =+SUM(N21:N23,N24:N27) -> 120906.75 | ... R28: =+SUM(R21:R23,R24:R27) -> 168029.9
B30: EQUITY AND LIABILITIES
B31: Equity | G31: =+SUM('Input Data'!E60:E61) -> -21245 | H31: =+SUM('Input Data'!F60:F61) -> -25188 | I31: =+SUM('Input Data'!G60:G61) -> -29936 | J31: =+SUM('Input Data'!H60:H61) -> -37390 | K31: =+SUM('Input Data'!I60:I61) -> -42358 | L31: =+L92 -> 28569.574 | M31: =+M92 -> 36504.851 | N31: =+N92 -> 46878.792 | O31: =+O92 -> 58018.256 | P31: =+P92 -> 69963.899 | Q31: =+Q92 -> 82758.59 | R31: =+R92 -> 96447.528 | T31: Forecasts include retained earnigs
B32: Retained earnings | G32: =+SUM('Input Data'!E62:E64) -> 37761 | H32: =+SUM('Input Data'!F62:F64) -> 41079 | I32: =+SUM('Input Data'!G62:G64) -> 49439 | J32: =+SUM('Input Data'!H62:H64) -> 56884 | K32: =+SUM('Input Data'!I62:I64) -> 63676
B33: TOTAL EQUITY | G33: =+SUM(G31:G32) -> 16516 | H33: =+SUM(H31:H32) -> 15891 | I33: =+SUM(I31:I32) -> 19503 | J33: =+SUM(J31:J32) -> 19494 | K33: =+SUM(K31:K32) -> 21318 | L33: =SUM(L31:L32) -> 28569.574 | M33: =SUM(M31:M32) -> 36504.851 | N33: =SUM(N31:N32) -> 46878.792 | O33: =SUM(O31:O32) -> 58018.256 | P33: =SUM(P31:P32) -> 69963.899 | Q33: =SUM(Q31:Q32) -> 82758.59 | R33: =SUM(R31:R32) -> 96447.528
B34: Financial liability | G34: =+'Input Data'!E52+'Input Data'!E55+'Input Data'!E49 -> 37789 | H34: =+'Input Data'!F52+'Input Data'!F55+'Input Data'!F49 -> 36993 | I34: =+'Input Data'!G52+'Input Data'!G55+'Input Data'!G49 -> 37878 | J34: =+'Input Data'!H52+'Input Data'!H55+'Input Data'!H49 -> 38409 | K34: =+'Input Data'!I52+'Input Data'!I55+'Input Data'!I49 -> 43330 | L34: =+L$72 -> 40907.767 | M34: =+M$72 -> 38315.977 | N34: =+N$72 -> 35542.763 | O34: =+O$72 -> 32575.423 | P34: =+P$72 -> 29400.369 | Q34: =+Q$72 -> 26003.062 | R34: =+R$72 -> 22367.943
B35: Other non current liabilities | G35: =+'Input Data'!E56 -> 10397 | H35: =+'Input Data'!F56 -> 8807 | I35: =+'Input Data'!G56 -> 8773 | J35: =+'Input Data'!H56 -> 8647 | K35: =+'Input Data'!I56 -> 10013 | L35: =+K35 -> 10013 | M35: =+L35 -> 10013 | N35: =+M35 -> 10013 | O35: =+N35 -> 10013 | P35: =+O35 -> 10013 | Q35: =+P35 -> 10013 | R35: =+Q35 -> 10013 | S35: *
B36: Trade and other payables | G36: =+'Input Data'!E50 -> 8154 | H36: =+'Input Data'!F50 -> 8689 | I36: =+'Input Data'!G50 -> 7906 | J36: =+'Input Data'!H50 -> 7675 | K36: =+'Input Data'!I50 -> 8968 | L36: =+L$62 -> 9284.7287 | M36: =+M$62 -> 9934.6597 | N36: =+N$62 -> 9957.2385 | O36: =+O$62 -> 10455.1 | P36: =+P$62 -> 10977.855 | Q36: =+Q$62 -> 11526.748 | R36: =+R$62 -> 12103.086
B37: Other current liabilities | G37: =+'Input Data'!E51+'Input Data'!E53 -> 9937 | H37: =+'Input Data'!F51+'Input Data'!F53 -> 11563 | I37: =+'Input Data'!G51+'Input Data'!G53 -> 13416 | J37: =+'Input Data'!H51+'Input Data'!H53 -> 13539 | K37: =+'Input Data'!I51+'Input Data'!I53 -> 14956 | L37: =+K37 -> 14956 | M37: =+L37 -> 14956 | N37: =+M37 -> 14956 | O37: =+N37 -> 14956 | P37: =+O37 -> 14956 | Q37: =+P37 -> 14956 | R37: =+Q37 -> 14956 | S37: *
B38: TOTAL LIABILITIES | G38: =+SUM(G34:G35,G36:G37) -> 66277 | H38: =+SUM(H34:H35,H36:H37) -> 66052 | I38: =+SUM(I34:I35,I36:I37) -> 67973 | J38: =+SUM(J34:J35,J36:J37) -> 68270 | K38: =+SUM(K34:K35,K36:K37) -> 77267 | L38: =+SUM(L34:L35,L36:L37) -> 75161.496 | M38: =+SUM(M34:M35,M36:M37) -> 73219.637 | N38: =+SUM(N34:N35,N36:N37) -> 70469.001 | ... R38: =+SUM(R34:R35,R36:R37) -> 59440.029
B39: TOTAL EQUITY AND LIABILITIES | G39: =+G33+G38 -> 82793 | H39: =+H33+H38 -> 81943 | I39: =+I33+I38 -> 87476 | J39: =+J33+J38 -> 87764 | K39: =+K33+K38 -> 98585 | L39: =+L33+L38 -> 103731.07 | M39: =+M33+M38 -> 109724.49 | N39: =+N33+N38 -> 117347.79 | ... R39: =+R33+R38 -> 155887.56
B41: Balance Sheet Check | G41: =IF(G28=G39,"OK",G28-G39) -> OK | H41: =IF(H28=H39,"OK",H28-H39) -> OK | I41: =IF(I28=I39,"OK",I28-I39) -> OK | J41: =IF(J28=J39,"OK",J28-J39) -> OK | K41: =IF(K28=K39,"OK",K28-K39) -> OK | L41: =IF(L28=L39,"OK",L28-L39) -> 868.91483 | M41: =IF(M28=M39,"OK",M28-M39) -> 3468.6389 | N41: =IF(N28=N39,"OK",N28-N39) -> 3558.954 | ... R41: =IF(R28=R39,"OK",R28-R39) -> 12142.342 | T41: Need to figure this out
B43: PPE Schedule
B45: PPE Schedule | G45: =+G18 -> 44561 | H45: =+H18 -> 44926 | I45: =+I18 -> 45291 | J45: =+J18 -> 45657 | K45: =+K18 -> 46022 | L45: =+L18 -> 46387 | M45: =+M18 -> 46752 | N45: =+N18 -> 47118 | ... R45: =+R18 -> 48579
B46: Beginning PPE | H46: =+G49 -> 12090 | I46: =+H49 -> 12028 | J46: =+I49 -> 12680 | K46: =+J49 -> 13361 | L46: =K49 -> 15140 | M46: =L49 -> 17108.2 | N46: =M49 -> 18049.151 | O46: =N49 -> 19041.854 | P46: =O49 -> 20089.156 | Q46: =P49 -> 21194.06 | R46: =Q49 -> 22359.733
B47: D&A | H47: =+'P&L'!H32 -> -2219 | I47: =+'P&L'!I32 -> -2144 | J47: =+'P&L'!J32 -> -2153 | K47: =+'P&L'!K32 -> -2262 | L47: =+-L46*L51 -> -2649.5 | M47: =+-M46*M51 -> -2993.935 | N47: =+-N46*N51 -> -3158.6014 | O47: =+-O46*O51 -> -3332.3245 | P47: =+-P46*P51 -> -3515.6024 | Q47: =+-Q46*Q51 -> -3708.9605 | R47: =+-R46*R51 -> -3912.9533
B48: Capex | H48: =+H49-H46-H47 -> 2157 | I48: =+I49-I46-I47 -> 2796 | J48: =+J49-J46-J47 -> 2834 | K48: =+K49-K46-K47 -> 4041 | L48: =+L46*L52 -> 4617.7 | M48: =+M46*M52 -> 3934.886 | N48: =+N46*N52 -> 4151.3047 | O48: =+O46*O52 -> 4379.6265 | P48: =+P46*P52 -> 4620.5059 | Q48: =+Q46*Q52 -> 4874.6338 | R48: =+R46*R52 -> 5142.7386
B49: Closing PPE | G49: =+G$21 -> 12090 | H49: =+H$21 -> 12028 | I49: =+I$21 -> 12680 | J49: =+J$21 -> 13361 | K49: =+K$21 -> 15140 | L49: =SUM(L46:L48) -> 17108.2 | M49: =SUM(M46:M48) -> 18049.151 | N49: =SUM(N46:N48) -> 19041.854 | O49: =SUM(O46:O48) -> 20089.156 | P49: =SUM(P46:P48) -> 21194.06 | Q49: =SUM(Q46:Q48) -> 22359.733 | R49: =SUM(R46:R48) -> 23589.519
B51: D&A as % of Beginning PPE | H51: =+H47/H46*-1 -> 0.18354012 | I51: =+I47/I46*-1 -> 0.17825075 | J51: =+J47/J46*-1 -> 0.16979495 | K51: =+K47/K46*-1 -> 0.16929871 | L51: =+'P&L'!$L16 -> 0.175 | M51: =+'P&L'!$L16 -> 0.175 | N51: =+'P&L'!$L16 -> 0.175 | O51: =+'P&L'!$L16 -> 0.175 | P51: =+'P&L'!$L16 -> 0.175 | Q51: =+'P&L'!$L16 -> 0.175 | R51: =+'P&L'!$L16 -> 0.175
...

Sheet Cash Flow
B2: Cash Flow Statement
B3: ='Cover Page'!E5&" | "&TEXT(TODAY(),"mmmm d, yyyy") -> Caterpillar Inc. (CAT) | February 11, 2026
B5: =+Assumptions!$D$11 -> USD' millions | S5: Scenario | T5: =+'P&L'!$T$5 -> BASE
B7: Cash Flow Statement
B9: Year End | G9: =+DATE(YEAR(H9)-1,MONTH(H9),DAY(H9)) -> 44561 | H9: =+DATE(YEAR(I9)-1,MONTH(I9),DAY(I9)) -> 44926 | I9: =+DATE(YEAR(J9)-1,MONTH(J9),DAY(J9)) -> 45291 | J9: =+DATE(YEAR(K9)-1,MONTH(K9),DAY(K9)) -> 45657 | K9: =+DATE(YEAR(Assumptions!$D$10)-1,MONTH(Assumptions!$D$10),DAY(Assumptions!$D$10)) -> 46022 | L9: =+DATE(YEAR(K9)+1,MONTH(K9),DAY(K9)) -> 46387 | M9: =+DATE(YEAR(L9)+1,MONTH(L9),DAY(L9)) -> 46752 | N9: =+DATE(YEAR(M9)+1,MONTH(M9),DAY(M9)) -> 47118 | O9: =+DATE(YEAR(N9)+1,MONTH(N9),DAY(N9)) -> 47483 | P9: =+DATE(YEAR(O9)+1,MONTH(O9),DAY(O9)) -> 47848 | Q9: =+DATE(YEAR(P9)+1,MONTH(P9),DAY(P9)) -> 48213 | R9: =+DATE(YEAR(Q9)+1,MONTH(Q9),DAY(Q9)) -> 48579
G10: Audited | H10: Audited | I10: Audited | J10: Audited | K10: Audited | L10: Fcst | M10: Fcst | N10: Fcst | O10: Fcst | P10: Fcst | Q10: Fcst | R10: Fcst
B12: EBIT | H12: =+'P&L'!H$34 -> 9195 | I12: =+'P&L'!I$34 -> 13561 | J12: =+'P&L'!J$34 -> 13885 | K12: =+'P&L'!K$34 -> 12043 | L12: =+'P&L'!L$34 -> 12212.307 | M12: =+'P&L'!M$34 -> 12908.199 | N12: =+'P&L'!N$34 -> 15813.689 | O12: =+'P&L'!O$34 -> 16588.58 | ... R12: =+'P&L'!R$34 -> 19147.984
B13: Tax | H13: =+'P&L'!H$37 -> -2067 | I13: =+'P&L'!I$37 -> -2781 | J13: =+'P&L'!J$37 -> -2629 | K13: =+'P&L'!K$37 -> -2768 | L13: =+'P&L'!L$37 -> -1927.6335 | M13: =+'P&L'!M$37 -> -2109.3776 | N13: =+'P&L'!N$37 -> -2757.6298 | O13: =+'P&L'!O$37 -> -2961.1232 | ... R13: =+'P&L'!R$37 -> -3638.8316
B14: NOPAT | H14: =+H12+H13 -> 7128 | I14: =+I12+I13 -> 10780 | J14: =+J12+J13 -> 11256 | K14: =+K12+K13 -> 9275 | L14: =+L12+L13 -> 10284.674 | M14: =+M12+M13 -> 10798.821 | N14: =+N12+N13 -> 13056.059 | O14: =+O12+O13 -> 13627.457 | ... R14: =+R12+R13 -> 15509.152
B15: Add-bAck D&A | H15: =+'P&L'!H$32*-1 -> 2219 | I15: =+'P&L'!I$32*-1 -> 2144 | J15: =+'P&L'!J$32*-1 -> 2153 | K15: =+'P&L'!K$32*-1 -> 2262 | L15: =+'P&L'!L$32*-1 -> 2649.5 | M15: =+'P&L'!M$32*-1 -> 2993.935 | N15: =+'P&L'!N$32*-1 -> 3158.6014 | O15: =+'P&L'!O$32*-1 -> 3332.3245 | ... R15: =+'P&L'!R$32*-1 -> 3912.9533
B16: Gross cash flow | H16: =+SUM(H14:H15) -> 9347 | I16: =+SUM(I14:I15) -> 12924 | J16: =+SUM(J14:J15) -> 13409 | K16: =+SUM(K14:K15) -> 11537 | L16: =+SUM(L14:L15) -> 12934.174 | M16: =+SUM(M14:M15) -> 13792.756 | N16: =+SUM(N14:N15) -> 16214.66 | O16: =+SUM(O14:O15) -> 16959.782 | ... R16: =+SUM(R14:R15) -> 19422.106
B18: Trade receivables | H18: =+('Balance Sheet '!H$25-'Balance Sheet '!G$25)*-1 -> -494 | I18: =+('Balance Sheet '!I$25-'Balance Sheet '!H$25)*-1 -> -951 | J18: =+('Balance Sheet '!J$25-'Balance Sheet '!I$25)*-1 -> -27 | K18: =+('Balance Sheet '!K$25-'Balance Sheet '!J$25)*-1 -> -2722 | L18: =+('Balance Sheet '!L$25-'Balance Sheet '!K$25)*-1 -> 566.41266 | M18: =+('Balance Sheet '!M$25-'Balance Sheet '!L$25)*-1 -> -1470.1811 | N18: =+('Balance Sheet '!N$25-'Balance Sheet '!M$25)*-1 -> -1123.6384 | O18: =+('Balance Sheet '!O$25-'Balance Sheet '!N$25)*-1 -> -1179.8203 | ... R18: =+('Balance Sheet '!R$25-'Balance Sheet '!Q$25)*-1 -> -1365.7895
B19: Inventory | H19: =+'Balance Sheet '!H$24-'Balance Sheet '!G$24 -> 2232 | I19: =+'Balance Sheet '!I$24-'Balance Sheet '!H$24 -> 295 | J19: =+'Balance Sheet '!J$24-'Balance Sheet '!I$24 -> 262 | K19: =+'Balance Sheet '!K$24-'Balance Sheet '!J$24 -> 1308 | L19: =+'Balance Sheet '!L$24-'Balance Sheet '!K$24 -> 434.45741 | M19: =+'Balance Sheet '!M$24-'Balance Sheet '!L$24 -> 1299.862 | N19: =+'Balance Sheet '!N$24-'Balance Sheet '!M$24 -> 45.157544 | O19: =+'Balance Sheet '!O$24-'Balance Sheet '!N$24 -> 995.72385 | ... R19: =+'Balance Sheet '!R$24-'Balance Sheet '!Q$24 -> 1152.6748
B20: Trade payables | H20: =+'Balance Sheet '!H$36-'Balance Sheet '!G$36 -> 535 | I20: =+'Balance Sheet '!I$36-'Balance Sheet '!H$36 -> -783 | J20: =+'Balance Sheet '!J$36-'Balance Sheet '!I$36 -> -231 | K20: =+'Balance Sheet '!K$36-'Balance Sheet '!J$36 -> 1293 | L20: =+'Balance Sheet '!L$36-'Balance Sheet '!K$36 -> 316.72871 | M20: =+'Balance Sheet '!M$36-'Balance Sheet '!L$36 -> 649.93101 | N20: =+'Balance Sheet '!N$36-'Balance Sheet '!M$36 -> 22.578772 | O20: =+'Balance Sheet '!O$36-'Balance Sheet '!N$36 -> 497.86192 | ... R20: =+'Balance Sheet '!R$36-'Balance Sheet '!Q$36 -> 576.33741
B21: Changes in working capital | H21: =+SUM(H18:H20) -> 2273 | I21: =+SUM(I18:I20) -> -1439 | J21: =+SUM(J18:J20) -> 4 | K21: =+SUM(K18:K20) -> -121 | L21: =+SUM(L18:L20) -> 1317.5988 | M21: =+SUM(M18:M20) -> 479.61191 | N21: =+SUM(N18:N20) -> -1055.9021 | O21: =+SUM(O18:O20) -> 313.76543 | ... R21: =+SUM(R18:R20) -> 363.2227
B23: Capex | H23: =+('Balance Sheet '!H21-'Balance Sheet '!G21)*-1+'P&L'!H32 -> -2157 | I23: =+('Balance Sheet '!I21-'Balance Sheet '!H21)*-1+'P&L'!I32 -> -2796 | J23: =+('Balance Sheet '!J21-'Balance Sheet '!I21)*-1+'P&L'!J32 -> -2834 | K23: =+('Balance Sheet '!K21-'Balance Sheet '!J21)*-1+'P&L'!K32 -> -4041 | L23: =+'Balance Sheet '!L$48*-1 -> -4617.7 | M23: =+'Balance Sheet '!M$48*-1 -> -3934.886 | N23: =+'Balance Sheet '!N$48*-1 -> -4151.3047 | O23: =+'Balance Sheet '!O$48*-1 -> -4379.6265 | P23: =+'Balance Sheet '!P$48*-1 -> -4620.5059 | Q23: =+'Balance Sheet '!Q$48*-1 -> -4874.6338 | R23: =+'Balance Sheet '!R$48*-1 -> -5142.7386
B24: Other assets | H24: =+('Balance Sheet '!H22-'Balance Sheet '!G22)*-1 -> 1320 | I24: =+('Balance Sheet '!I22-'Balance Sheet '!H22)*-1 -> 174 | J24: =+('Balance Sheet '!J22-'Balance Sheet '!I22)*-1 -> 232 | K24: =+('Balance Sheet '!K22-'Balance Sheet '!J22)*-1 -> 78 | L24: =+('Balance Sheet '!L22-'Balance Sheet '!K22)*-1 -> 0 | M24: =+('Balance Sheet '!M22-'Balance Sheet '!L22)*-1 -> 0 | N24: =+('Balance Sheet '!N22-'Balance Sheet '!M22)*-1 -> 0 | O24: =+('Balance Sheet '!O22-'Balance Sheet '!N22)*-1 -> 0 | ... R24: =+('Balance Sheet '!R22-'Balance Sheet '!Q22)*-1 -> 0
B25: Other liabilities | H25: =+('Balance Sheet '!H35-'Balance Sheet '!G35)+('Balance Sheet '!H37-'Balance Sheet '!G37) -> 36 | I25: =+('Balance Sheet '!I35-'Balance Sheet '!H35)+('Balance Sheet '!I37-'Balance Sheet '!H37) -> 1819 | J25: =+('Balance Sheet '!J35-'Balance Sheet '!I35)+('Balance Sheet '!J37-'Balance Sheet '!I37) -> -3 | K25: =+('Balance Sheet '!K35-'Balance Sheet '!J35)+('Balance Sheet '!K37-'Balance Sheet '!J37) -> 2783 | L25: =+('Balance Sheet '!L35-'Balance Sheet '!K35)+('Balance Sheet '!L37-'Balance Sheet '!K37) -> 0 | M25: =+('Balance Sheet '!M35-'Balance Sheet '!L35)+('Balance Sheet '!M37-'Balance Sheet '!L37) -> 0 | N25: =+('Balance Sheet '!N35-'Balance Sheet '!M35)+('Balance Sheet '!N37-'Balance Sheet '!M37) -> 0 | O25: =+('Balance Sheet '!O35-'Balance Sheet '!N35)+('Balance Sheet '!O37-'Balance Sheet '!N37) -> 0 | ... R25: =+('Balance Sheet '!R35-'Balance Sheet '!Q35)+('Balance Sheet '!R37-'Balance Sheet '!Q37) -> 0
B26: Unlevered free cash flow | H26: =+H16+H21+SUM(H23:H25) -> 10819 | I26: =+I16+I21+SUM(I23:I25) -> 10682 | J26: =+J16+J21+SUM(J23:J25) -> 10808 | K26: =+K16+K21+SUM(K23:K25) -> 10236 | L26: =+L16+L21+SUM(L23:L25) -> 9634.0725 | M26: =+M16+M21+SUM(M23:M25) -> 10337.482 | N26: =+N16+N21+SUM(N23:N25) -> 11007.454 | O26: =+O16+O21+SUM(O23:O25) -> 12893.92 | ... R26: =+R16+R21+SUM(R23:R25) -> 14642.59
B27: Interest | H27: =+'P&L'!H$35 -> -443 | I27: =+'P&L'!I$35 -> -511 | J27: =+'P&L'!J$35 -> -512 | K27: =+'P&L'!K$35 -> -502 | L27: =+'P&L'!L$35 -> -3033.1 | M27: =+'P&L'!M$35 -> -2863.5437 | N27: =+'P&L'!N$35 -> -2682.1184 | O27: =+'P&L'!O$35 -> -2487.9934 | ... R27: =+'P&L'!R$35 -> -1820.2143
B28: Financial liabilities | H28: =+'Balance Sheet '!H$34-'Balance Sheet '!G$34 -> -796 | I28: =+'Balance Sheet '!I$34-'Balance Sheet '!H$34 -> 885 | J28: =+'Balance Sheet '!J$34-'Balance Sheet '!I$34 -> 531 | K28: =+'Balance Sheet '!K$34-'Balance Sheet '!J$34 -> 4921 | L28: =+'Balance Sheet '!L$34-'Balance Sheet '!K$34 -> -2422.2332 | M28: =+'Balance Sheet '!M$34-'Balance Sheet '!L$34 -> -2591.7895 | N28: =+'Balance Sheet '!N$34-'Balance Sheet '!M$34 -> -2773.2148 | O28: =+'Balance Sheet '!O$34-'Balance Sheet '!N$34 -> -2967.3398 | ... R28: =+'Balance Sheet '!R$34-'Balance Sheet '!Q$34 -> -3635.1188
B29: Minority interest
B31: Other cash flow (plug) | H31: =+H32-SUM(H26:H28) -> -11830 | I31: =+I32-SUM(I26:I28) -> -11082 | J31: =+J32-SUM(J26:J28) -> -10916 | K31: =+K32-SUM(K26:K28) -> -11564
B32: Net cash flow | H32: =+H34-H33 -> -2250 | I32: =+I34-I33 -> -26 | J32: =+J34-J33 -> -89 | K32: =+K34-K33 -> 3091 | L32: =+SUM(L26:L31) -> 4178.7393 | M32: =+SUM(M26:M31) -> 4882.1489 | N32: =+SUM(N26:N31) -> 5552.1205 | O32: =+SUM(O26:O31) -> 7438.5873 | P32: =+SUM(P26:P31) -> 7995.1403 | Q32: =+SUM(Q26:Q31) -> 8577.6366 | R32: =+SUM(R26:R31) -> 9187.2566
B33: Opening Cash Balance | H33: =+G34 -> 9254 | I33: =+H34 -> 7004 | J33: =+I34 -> 6978 | K33: =+J34 -> 6889 | L33: =+K34 -> 9980 | M33: =+L34 -> 14158.739 | N33: =+M34 -> 19040.888 | O33: =+N34 -> 24593.009 | ... R33: =+Q34 -> 48604.373
B34: Closing Cash Balance | G34: =+'Balance Sheet '!G$26 -> 9254 | H34: =+'Balance Sheet '!H$26 -> 7004 | I34: =+'Balance Sheet '!I$26 -> 6978 | J34: =+'Balance Sheet '!J$26 -> 6889 | K34: =+'Balance Sheet '!K$26 -> 9980 | L34: =+SUM(L32:L33) -> 14158.739 | M34: =+SUM(M32:M33) -> 19040.888 | N34: =+SUM(N32:N33) -> 24593.009 | O34: =+SUM(O32:O33) -> 32031.596 | P34: =+SUM(P32:P33) -> 40026.736 | Q34: =+SUM(Q32:Q33) -> 48604.373 | R34: =+SUM(R32:R33) -> 57791.63
B36: Net cas flow check
B38: EBITDA/FCF%
B40: Cash Ratios
B41: FCF margin | H41: =+H26/'P&L'!H24 -> 0.18205529 | I41: =+I26/'P&L'!I24 -> 0.15929019 | J41: =+J26/'P&L'!J24 -> 0.16676696 | K41: =+K26/'P&L'!K24 -> 0.15144476 | L41: =+L26/'P&L'!L24 -> 0.13321407 | M41: =+M26/'P&L'!M24 -> 0.13358915 | N41: =+N26/'P&L'!N24 -> 0.13547339 | O41: =+O26/'P&L'!O24 -> 0.15113422 | ... R41: =+R26/'P&L'!R24 -> 0.14826131
B42: FCF growth | I42: =+(I26-H26)/H26 -> -0.012662908 | J42: =+(J26-I26)/I26 -> 0.011795544 | K42: =+(K26-J26)/J26 -> -0.05292376
B43: FCF return on capital | H43: =+H34/('Balance Sheet '!G33+'Balance Sheet '!G38-SUM('Balance Sheet '!G36:G37)-'Balance Sheet '!G26) -> 0.12631655 | I43: =+I26/('Balance Sheet '!H33+'Balance Sheet '!H38-SUM('Balance Sheet '!H36:H37)-'Balance Sheet '!H26) -> 0.19532979 | J43: =+J26/('Balance Sheet '!I33+'Balance Sheet '!I38-SUM('Balance Sheet '!I36:I37)-'Balance Sheet '!I26) -> 0.18264161 | K43: =+K26/('Balance Sheet '!J33+'Balance Sheet '!J38-SUM('Balance Sheet '!J36:J37)-'Balance Sheet '!J26) -> 0.17156937

Sheet DCF Model
B2: DCF Model
B3: ='Cover Page'!E5&" | "&TEXT(TODAY(),"mmmm d, yyyy") -> Caterpillar Inc. (CAT) | February 11, 2026
B5: =+Assumptions!D11 -> USD' millions | S5: Scenario | T5: =+'P&L'!$T$5 -> BASE
B7: DCF Analysis
B9: Assumptions | K9: WACC (Discount Rate)
K10: Cost of debt | M10: =+D14 -> 0.0675
B11: Valuation date | D11: =TODAY() -> 46064 | F11: Analysis date | K11: Tax rate | M11: =+D13 -> 0.21
B12: Financial year end | D12: =+Assumptions!$D$10 -> 46387 | K12: After tax cost of debt | M12: =M10*(1-M11) -> 0.053325
B13: Tax rate | D13: 0.21
B14: Cost of debt | D14: 0.0675 | K14: Expected market return | M14: =+D15 -> 0.145
B15: Expected market return | D15: 0.145 | F15: S&P annual return (5 year period) | K15: Risk Free Rate | M15: =+D16 -> 0.041
B16: Risk free rate | D16: 0.041 | F16: 10-year treasury note yield | K16: Market Risk Premium | M16: =+M14-M15 -> 0.104
B17: Beta | D17: 1.55
B18: EV/EBITDA Multiple | K18: Avg. comps beta | M18: =+D17 -> 1.55
B19: Terminal growth rate | D19: 0.03 | K19: Cost of equity | M19: =M15+(M16*M18) -> 0.2022
B20: Current price | D20: 726.5 | F20: As per market
B21: Shares outstanding | D21: 478 | K21: Target debt to EV | M21: 0.7
B22: Debt | K22: Target equity to EV | M22: 0.3
B23: Cash | K23: WACC | M23: =(M12*M21)+(M19*M22) -> 0.0979875
B25: Discounted Cash Flow | F25: Entry | G25: =YEAR(G26) -> 2026 | H25: =YEAR(H26) -> 2027 | I25: =YEAR(I26) -> 2028 | J25: =YEAR(J26) -> 2029 | K25: =YEAR(K26) -> 2030 | L25: =YEAR(L26) -> 2031 | M25: =YEAR(M26) -> 2032
B26: Date | F26: =+D11 -> 46064 | G26: =DATE(YEAR($D$12)+F27,MONTH($D$12),DAY($D$12)) -> 46387 | H26: =DATE(YEAR($D$12)+G27,MONTH($D$12),DAY($D$12)) -> 46752 | I26: =DATE(YEAR($D$12)+H27,MONTH($D$12),DAY($D$12)) -> 47118 | J26: =DATE(YEAR($D$12)+I27,MONTH($D$12),DAY($D$12)) -> 47483 | K26: =DATE(YEAR($D$12)+J27,MONTH($D$12),DAY($D$12)) -> 47848 | L26: =DATE(YEAR($D$12)+K27,MONTH($D$12),DAY($D$12)) -> 48213 | M26: =DATE(YEAR($D$12)+L27,MONTH($D$12),DAY($D$12)) -> 48579
B27: Time Periods | F27: 0 | G27: =F27+1 -> 1 | H27: =G27+1 -> 2 | I27: =H27+1 -> 3 | J27: =I27+1 -> 4 | K27: =J27+1 -> 5 | L27: =K27+1 -> 6 | M27: =L27+1 -> 7
B28: Year Fraction | G28: =YEARFRAC(F26,G26) -> 0.88888889 | H28: =YEARFRAC(G26,H26) -> 1 | I28: =YEARFRAC(H26,I26) -> 1 | J28: =YEARFRAC(I26,J26) -> 1 | K28: =YEARFRAC(J26,K26) -> 1 | L28: =YEARFRAC(K26,L26) -> 1 | M28: =YEARFRAC(L26,M26) -> 1
B30: EBIT | G30: =+'P&L'!L34 -> 12212.307 | H30: =+'P&L'!M34 -> 12908.199 | I30: =+'P&L'!N34 -> 15813.689 | J30: =+'P&L'!O34 -> 16588.58 | K30: =+'P&L'!P34 -> 17401.348 | L30: =+'P&L'!Q34 -> 18253.837 | M30: =+'P&L'!R34 -> 19147.984
B31: Less: Cash taxes | G31: ='P&L'!L37 -> -1927.6335 | H31: ='P&L'!M37 -> -2109.3776 | I31: ='P&L'!N37 -> -2757.6298 | J31: ='P&L'!O37 -> -2961.1232 | K31: ='P&L'!P37 -> -3175.4243 | L31: ='P&L'!Q37 -> -3401.1203 | M31: ='P&L'!R37 -> -3638.8316
B32: Plus: D&A | G32: =+'P&L'!L32*-1 -> 2649.5 | H32: =+'P&L'!M32*-1 -> 2993.935 | I32: =+'P&L'!N32*-1 -> 3158.6014 | J32: =+'P&L'!O32*-1 -> 3332.3245 | K32: =+'P&L'!P32*-1 -> 3515.6024 | L32: =+'P&L'!Q32*-1 -> 3708.9605 | M32: =+'P&L'!R32*-1 -> 3912.9533
B33: Less: Capex | G33: =+'Balance Sheet '!L48*-1 -> -4617.7 | H33: =+'Balance Sheet '!M48*-1 -> -3934.886 | I33: =+'Balance Sheet '!N48*-1 -> -4151.3047 | J33: =+'Balance Sheet '!O48*-1 -> -4379.6265 | K33: =+'Balance Sheet '!P48*-1 -> -4620.5059 | L33: =+'Balance Sheet '!Q48*-1 -> -4874.6338 | M33: =+'Balance Sheet '!R48*-1 -> -5142.7386
B34: Less: Changes in NWC | G34: =+'Cash Flow'!L21 -> 1317.5988 | H34: =+'Cash Flow'!M21 -> 479.61191 | I34: =+'Cash Flow'!N21 -> -1055.9021 | J34: =+'Cash Flow'!O21 -> 313.76543 | K34: =+'Cash Flow'!P21 -> 329.4537 | L34: =+'Cash Flow'!Q21 -> 345.92639 | M34: =+'Cash Flow'!R21 -> 363.2227
B35: Unlevered free cash flow | G35: =SUM(G30:G34) -> 9634.0725 | H35: =SUM(H30:H34) -> 10337.482 | I35: =SUM(I30:I34) -> 11007.454 | J35: =SUM(J30:J34) -> 12893.92 | K35: =SUM(K30:K34) -> 13450.473 | L35: =SUM(L30:L34) -> 14032.97 | M35: =SUM(M30:M34) -> 14642.59
B36: Terminal Value | M36: =P45 -> 221832.95
B37: Transaction CF | G37: =SUM(G35:G36)*G28 -> 8563.62 | H37: =SUM(H35:H36)*H28 -> 10337.482 | I37: =SUM(I35:I36)*I28 -> 11007.454 | J37: =SUM(J35:J36)*J28 -> 12893.92 | K37: =SUM(K35:K36)*K28 -> 13450.473 | L37: =SUM(L35:L36)*L28 -> 14032.97 | M37: =SUM(M35:M36)*M28 -> 236475.54
B38: Total Unlevered free cash flow | G38: =G37 -> 8563.62 | H38: =H37 -> 10337.482 | I38: =I37 -> 11007.454 | J38: =J37 -> 12893.92 | K38: =K37 -> 13450.473 | L38: =L37 -> 14032.97 | M38: =M37 -> 236475.54
B42: Intrinsic Value | F42: Market Value | J42: Market Value vs Intrinsic Value | N42: Terminal Value
B43: Enterprise value (XNPV) | D43: =+XNPV(M23,G38:M38,G26:M26) -> 189778.11 | F43: Market cap | H43: 340209 | J43: Market value | L43: =+H48 -> 726.5 | N43: Terminal growth | P43: =(M35*(1+D19))/(M23-D19) -> 221832.95
B44: Plus: Cash | D44: =+'Balance Sheet '!K26 -> 9980 | F44: Plus: Debt | H44: =+'Balance Sheet '!K34 -> 43330 | J44: Intrinsic value | L44: =+D48 -> 327.25546 | N44: EV/EBITDA
B45: Less: Debt | D45: =+'Balance Sheet '!K34 -> 43330 | F45: Less: Cash | H45: =+'Balance Sheet '!K26 -> 9980 | J45: Implied upside/(downside) | L45: =+L44-L43 -> -399.24454 | N45: Average | P45: =AVERAGE(P43:P44) -> 221832.95
B46: Equity value | D46: =+D43+D44-D45 -> 156428.11 | F46: Enterprise value | H46: =+H43+H44-H45 -> 373559
J47: Rate of Return
B48: Equity value/share | D48: =+D46/D21 -> 327.25546 | F48: Equity value/share | H48: =+D20 -> 726.5 | J48: Price upside/(downside) | L48: =+L45/L44 -> -1.2199783
N49: IRR > WACC = Undervalued
...

Sheet Comps Table
B2: Comparable Company Analysis
B3: ='Cover Page'!E5&" | "&TEXT(TODAY(),"mmmm d, yyyy") -> Caterpillar Inc. (CAT) | February 11, 2026
B6: TTM Basis
B7: Company name | E7: Market Data | I7: Financial Data | N7: Valuation
E8: Price | F8: Market Cap | G8: EV | I8: Revenue | J8: EBITDA | K8: EBIT | L8: Earnings | N8: EV/Revenue | O8: EV/EBITDA | P8: EV/EBIT | Q8: P/E
E9: (USD/share) | F9: (USDm) | G9: (USDm) | I9: (USDm) | J9: (USDm) | K9: (USDm) | L9: (USDm) | N9: x | O9: x | P9: x | Q9: x
B10: Caterpillar | E10: 726 | F10: 340209 | G10: 103.9 | I10: 23.95 | J10: 6.869 | K10: 4.207 | L10: 2.791 | N10: =+G10/I10 -> 4.3382046 | O10: =+G10/J10 -> 15.125928 | P10: =+G10/K10 -> 24.696934 | Q10: =+F10/L10 -> 121895.02
B11: Deere & Co | E11: 568 | F11: 158066 | N11: =+G11/I11 -> #DIV/0! | O11: =+G11/J11 -> #DIV/0! | P11: =+G11/K11 -> #DIV/0! | Q11: =+F11/L11 -> #DIV/0!
B12: Terex | E12: 62 | F12: 7119 | N12: =+G12/I12 -> #DIV/0! | O12: =+G12/J12 -> #DIV/0! | P12: =+G12/K12 -> #DIV/0! | Q12: =+F12/L12 -> #DIV/0!
B13: Komatsu | N13: =+G13/I13 -> #DIV/0! | O13: =+G13/J13 -> #DIV/0! | P13: =+G13/K13 -> #DIV/0! | Q13: =+F13/L13 -> #DIV/0!
B14: Hitachi
B15: Cummins
B16: Mean
B17: Median

Sheet Output Charts
B2: Output Charts
B3: ='Cover Page'!E5&" | "&TEXT(TODAY(),"mmmm d, yyyy") -> Caterpillar Inc. (CAT) | February 11, 2026
P5: Scenario | Q5: =+'P&L'!$T$5 -> BASE

Sheet Ratio Analysis
B2: Ratio Analysis
B3: ='Cover Page'!E5&" | "&TEXT(TODAY(),"mmmm d, yyyy") -> Caterpillar Inc. (CAT) | February 11, 2026
F5: =+DATE(YEAR(G5)-1,MONTH(G5),DAY(G5)) -> 44561 | G5: =+DATE(YEAR(H5)-1,MONTH(H5),DAY(H5)) -> 44926 | H5: =+DATE(YEAR(I5)-1,MONTH(I5),DAY(I5)) -> 45291 | I5: =+DATE(YEAR(J5)-1,MONTH(J5),DAY(J5)) -> 45657 | J5: =+DATE(YEAR(Assumptions!D10)-1,MONTH(Assumptions!D10),DAY(Assumptions!D10)) -> 46022
B7: Days Per Period | F7: 365 | G7: 365 | H7: 365 | I7: 365 | J7: 365
B8: Profitabilty
B9: Gross profit margin | F9: =+'P&L'!G$26/'P&L'!G$24 -> 0.30327049 | G9: =+'P&L'!H$26/'P&L'!H$24 -> 0.30418833 | H9: =+'P&L'!I$26/'P&L'!I$24 -> 0.36225768 | I9: =+'P&L'!J$26/'P&L'!J$24 -> 0.37973121 | J9: =+'P&L'!K$26/'P&L'!K$24 -> 0.33788042
B10: EBITDA margin | F10: =+'P&L'!G$45/'P&L'!G$24 -> 0.18108336 | G10: =+'P&L'!H$45/'P&L'!H$24 -> 0.17034345 | H10: =+'P&L'!I$45/'P&L'!I$24 -> 0.22532061 | I10: =+'P&L'!J$45/'P&L'!J$24 -> 0.23492108 | J10: =+'P&L'!K$45/'P&L'!K$24 -> 0.19844945
B11: Return on assets (ROA) | G11: =+'P&L'!H38/AVERAGE('Balance Sheet '!G28:H28) -> 0.081160159 | H11: =+'P&L'!I38/AVERAGE('Balance Sheet '!H28:I28) -> 0.12122607 | I11: =+'P&L'!J38/AVERAGE('Balance Sheet '!I28:J28) -> 0.12262041 | J11: =+'P&L'!K38/AVERAGE('Balance Sheet '!J28:K28) -> 0.094156663
B12: Return on equity (ROE) | G12: =+'P&L'!H38/AVERAGE('Balance Sheet '!G33:H33) -> 0.41256519 | H12: =+'P&L'!I38/AVERAGE('Balance Sheet '!H33:I33) -> 0.58026784 | I12: =+'P&L'!J38/AVERAGE('Balance Sheet '!I33:J33) -> 0.55101674 | J12: =+'P&L'!K38/AVERAGE('Balance Sheet '!J33:K33) -> 0.42992257
B13: Return on invested capital (ROIC) | F13: =+'P&L'!G38/('Balance Sheet '!G33+'Balance Sheet '!G34) -> 0.11899457 | G13: =+'P&L'!H38/('Balance Sheet '!H33+'Balance Sheet '!H34) -> 0.12640874 | H13: =+'P&L'!I38/('Balance Sheet '!I33+'Balance Sheet '!I34) -> 0.17896168 | I13: =+'P&L'!J38/('Balance Sheet '!J33+'Balance Sheet '!J34) -> 0.1855517 | J13: =+'P&L'!K38/('Balance Sheet '!K33+'Balance Sheet '!K34) -> 0.13570412
B15: Liquidity
B16: Current ratio | F16: =+SUM('Balance Sheet '!G26:G27)/SUM('Balance Sheet '!G36:G37) -> 0.66563485 | G16: =+SUM('Balance Sheet '!H26:H27)/SUM('Balance Sheet '!H36:H37) -> 0.47629864 | H16: =+SUM('Balance Sheet '!I26:I27)/SUM('Balance Sheet '!I36:I37) -> 0.54235062 | I16: =+SUM('Balance Sheet '!J26:J27)/SUM('Balance Sheet '!J36:J37) -> 0.47176393 | J16: =+SUM('Balance Sheet '!K26:K27)/SUM('Balance Sheet '!K36:K37) -> 0.53423341
B17: Cash ratio | F17: =+'Balance Sheet '!G26/SUM('Balance Sheet '!G36:G37) -> 0.51152507 | G17: =+'Balance Sheet '!H26/SUM('Balance Sheet '!H36:H37) -> 0.34584239 | H17: =+'Balance Sheet '!I26/SUM('Balance Sheet '!I36:I37) -> 0.32726761 | I17: =+'Balance Sheet '!J26/SUM('Balance Sheet '!J36:J37) -> 0.32473838 | J17: =+'Balance Sheet '!K26/SUM('Balance Sheet '!K36:K37) -> 0.41715432
B18: Operating cash flow ratio | H18: ='P&L'!#REF!/'P&L'!#REF! -> #REF! | I18: ='P&L'!#REF!/'P&L'!#REF! -> #REF! | J18: ='P&L'!#REF!/'P&L'!#REF! -> #REF!
B19: Cash conversion ratio | G19: =+'Cash Flow'!H$26/'P&L'!H$38 -> 1.6183994 | H19: =+'Cash Flow'!I$26/'P&L'!I$38 -> 1.0402181 | I19: =+'Cash Flow'!J$26/'P&L'!J$38 -> 1.0059568 | J19: =+'Cash Flow'!K$26/'P&L'!K$38 -> 1.1667617
B21: Leverage & Solvancy
B22: Debt ratio | F22: =+'Balance Sheet '!G38/'Balance Sheet '!G28 -> 0.80051454 | G22: =+'Balance Sheet '!H38/'Balance Sheet '!H28 -> 0.80607251 | H22: =+'Balance Sheet '!I38/'Balance Sheet '!I28 -> 0.77704742 | I22: =+'Balance Sheet '!J38/'Balance Sheet '!J28 -> 0.77788159 | J22: =+'Balance Sheet '!K38/'Balance Sheet '!K28 -> 0.78376021
B23: Net debt to equity (D/E) | F23: =+('Balance Sheet '!G34-'Balance Sheet '!G26)/'Balance Sheet '!G33 -> 1.7277186 | G23: =+('Balance Sheet '!H34-'Balance Sheet '!H26)/'Balance Sheet '!H33 -> 1.8871688 | H23: =+('Balance Sheet '!I34-'Balance Sheet '!I26)/'Balance Sheet '!I33 -> 1.5843716 | I23: =+('Balance Sheet '!J34-'Balance Sheet '!J26)/'Balance Sheet '!J33 -> 1.6169078 | J23: =+('Balance Sheet '!K34-'Balance Sheet '!K26)/'Balance Sheet '!K33 -> 1.5644057
B24: Interest coverage ( w EBITDA) | F24: =+'P&L'!G45/'P&L'!G35*-1 -> 18.913934 | G24: =+'P&L'!H45/'P&L'!H35*-1 -> 22.851016 | H24: =+'P&L'!I45/'P&L'!I35*-1 -> 29.569472 | I24: =+'P&L'!J45/'P&L'!J35*-1 -> 29.736328 | J24: =+'P&L'!K45/'P&L'!K35*-1 -> 26.719124
B25: Net debt to EBITDA | F25: =+('Balance Sheet '!G34-'Balance Sheet '!G26)/'P&L'!G45 -> 3.0915493 | G25: =+('Balance Sheet '!H34-'Balance Sheet '!H26)/'P&L'!H45 -> 2.9624617 | H25: =+('Balance Sheet '!I34-'Balance Sheet '!I26)/'P&L'!I45 -> 2.0450033 | I25: =+('Balance Sheet '!J34-'Balance Sheet '!J26)/'P&L'!J45 -> 2.0702791 | J25: =+('Balance Sheet '!K34-'Balance Sheet '!K26)/'P&L'!K45 -> 2.4863938
B26: Total debit to capital | F26: =+'Balance Sheet '!G34/(SUM('Balance Sheet '!G33:G34)) -> 0.69586594 | G26: =+'Balance Sheet '!H34/(SUM('Balance Sheet '!H33:H34)) -> 0.69951214 | H26: =+'Balance Sheet '!I34/(SUM('Balance Sheet '!I33:I34)) -> 0.66011398 | I26: =+'Balance Sheet '!J34/(SUM('Balance Sheet '!J33:J34)) -> 0.66333351 | J26: =+'Balance Sheet '!K34/(SUM('Balance Sheet '!K33:K34)) -> 0.67024502
B27: Equity multiplier (Asset to equity) | G27: =+AVERAGE('Balance Sheet '!G28:H28)/AVERAGE('Balance Sheet '!G33:H33) -> 5.0833462 | H27: =+AVERAGE('Balance Sheet '!H28:I28)/AVERAGE('Balance Sheet '!H33:I33) -> 4.7866588 | I27: =+AVERAGE('Balance Sheet '!I28:J28)/AVERAGE('Balance Sheet '!I33:J33) -> 4.493679 | J27: =+AVERAGE('Balance Sheet '!J28:K28)/AVERAGE('Balance Sheet '!J33:K33) -> 4.5660345
B29: Efficiency
B30: Operating ratio | F30: =+('P&L'!G25+'P&L'!G28)/'P&L'!G24*-1 -> 0.86506052 | G30: =+('P&L'!H25+'P&L'!H28)/'P&L'!H24*-1 -> 0.86699648 | H30: =+('P&L'!I25+'P&L'!I28)/'P&L'!I24*-1 -> 0.80665076 | I30: =+('P&L'!J25+'P&L'!J28)/'P&L'!J24*-1 -> 0.79829962 | J30: =+('P&L'!K25+'P&L'!K28)/'P&L'!K24*-1 -> 0.83501753
B31: Asset turnover | G31: =+'P&L'!H24/AVERAGE('Balance Sheet '!G28:H28) -> 0.72148164 | H31: =+'P&L'!I24/AVERAGE('Balance Sheet '!H28:I28) -> 0.79164675 | I31: =+'P&L'!J24/AVERAGE('Balance Sheet '!I28:J28) -> 0.7396599 | J31: =+'P&L'!K24/AVERAGE('Balance Sheet '!J28:K28) -> 0.72540234
B32: Trade receivable turnover | G32: =+'P&L'!H24/AVERAGE('Balance Sheet '!G25:H25) -> 3.3723187 | H32: =+'P&L'!I24/AVERAGE('Balance Sheet '!H25:I25) -> 3.6555916 | I32: =+'P&L'!J24/AVERAGE('Balance Sheet '!I25:J25) -> 3.4411554 | J32: =+'P&L'!K24/AVERAGE('Balance Sheet '!J25:K25) -> 3.3446655
B33: Trade receivable days | G33: =+AVERAGE('Balance Sheet '!G25:H25)/'P&L'!H24*'P&L'!H8 -> 108.23414 | H33: =+AVERAGE('Balance Sheet '!H25:I25)/'P&L'!I24*'P&L'!I8 -> 99.84704 | I33: =+AVERAGE('Balance Sheet '!I25:J25)/'P&L'!J24*'P&L'!J8 -> 106.06903 | J33: =+AVERAGE('Balance Sheet '!J25:K25)/'P&L'!K24*'P&L'!K8 -> 109.129
B34: Inventory turnover | G34: =+'P&L'!H25/AVERAGE('Balance Sheet '!G24:H24)*-1 -> 2.7286525 | H34: =+'P&L'!I25/AVERAGE('Balance Sheet '!H24:I24)*-1 -> 2.6049642 | I34: =+'P&L'!J25/AVERAGE('Balance Sheet '!I24:J24)*-1 -> 2.4077024 | J34: =+'P&L'!K25/AVERAGE('Balance Sheet '!J24:K24)*-1 -> 2.5600366
B35: Inventory days | G35: =+AVERAGE('Balance Sheet '!G24:H24)/'P&L'!H25*'P&L'!H8*-1 -> 133.76566 | H35: =+AVERAGE('Balance Sheet '!H24:I24)/'P&L'!I25*'P&L'!I8*-1 -> 140.11709 | I35: =+AVERAGE('Balance Sheet '!I24:J24)/'P&L'!J25*'P&L'!J8*-1 -> 151.59681 | J35: =+AVERAGE('Balance Sheet '!J24:K24)/'P&L'!K25*'P&L'!K8*-1 -> 142.57609
B36: Trade payable turnover | G36: =+'P&L'!H25/AVERAGE('Balance Sheet '!G36:H36)*-1 -> 4.9100517 | H36: =+'P&L'!I25/AVERAGE('Balance Sheet '!H36:I36)*-1 -> 5.1542031 | I36: =+'P&L'!J25/AVERAGE('Balance Sheet '!I36:J36)*-1 -> 5.1600026 | J36: =+'P&L'!K25/AVERAGE('Balance Sheet '!J36:K36)*-1 -> 5.3778766
B37: Trade payable days | G37: =+AVERAGE('Balance Sheet '!G36:H36)/'P&L'!H25*'P&L'!H8*-1 -> 74.337304 | H37: =+AVERAGE('Balance Sheet '!H36:I36)/'P&L'!I25*'P&L'!I8*-1 -> 70.815991 | I37: =+AVERAGE('Balance Sheet '!I36:J36)/'P&L'!J25*'P&L'!J8*-1 -> 70.736399 | J37: =+AVERAGE('Balance Sheet '!J36:K36)/'P&L'!K25*'P&L'!K8*-1 -> 67.870654
B39: Market value

Sheet Assumptions
B2: Assumptions
B3: ='Cover Page'!E5&" | "&TEXT(TODAY(),"mmmm d, yyyy") -> Caterpillar Inc. (CAT) | February 11, 2026
B7: General
B9: Analysis date | D9: =TODAY() -> 46064
B10: Financial year end | D10: 46387
B11: Reporting currency | D11: USD' millions
B15: Income Statement Drivers | G15: =+DATE(YEAR(D10),MONTH(D10),DAY(D10)) -> 46387 | H15: =+DATE(YEAR(G15)+1,MONTH(G15),DAY(G15)) -> 46752 | I15: =+DATE(YEAR(H15)+1,MONTH(H15),DAY(H15)) -> 47118 | J15: =+DATE(YEAR(I15)+1,MONTH(I15),DAY(I15)) -> 47483 | K15: =+DATE(YEAR(J15)+1,MONTH(J15),DAY(J15)) -> 47848 | L15: =+DATE(YEAR(K15)+1,MONTH(K15),DAY(K15)) -> 48213 | M15: =+DATE(YEAR(L15)+1,MONTH(L15),DAY(L15)) -> 48579
B17: Revenue growth (% change)
B18: BASE | G18: 0.07 | H18: 0.07 | I18: 0.05 | J18: 0.05 | K18: 0.05 | L18: 0.05 | M18: 0.05
B19: LOW | G19: 0.09 | H19: 0.09 | I19: 0.095 | J19: 0.095 | K19: 0.095 | L19: 0.095 | M19: 0.095
B20: HIGH | G20: 0.101 | H20: 0.101 | I20: 0.101 | J20: 0.101 | K20: 0.101 | L20: 0.101 | M20: 0.101
B22: Cost of sales (% of revenue)
B23: BASE | G23: 0.66 | H23: 0.66 | I23: 0.63 | J23: 0.63 | K23: 0.63 | L23: 0.63 | M23: 0.63
B24: LOW | G24: 0.23 | H24: 0.23 | I24: 0.22 | J24: 0.22 | K24: 0.22 | L24: 0.22 | M24: 0.22
B25: HIGH | G25: 0.57 | H25: 0.57 | I25: 0.57 | J25: 0.57 | K25: 0.57 | L25: 0.57 | M25: 0.57
B27: Sales, general and administrative (% of revenue)
B28: BASE | G28: 0.0635 | H28: 0.0635 | I28: 0.0645 | J28: 0.0645 | K28: 0.0645 | L28: 0.0645 | M28: 0.0645
B29: LOW | G29: 0.11 | H29: 0.11 | I29: 0.11 | J29: 0.11 | K29: 0.11 | L29: 0.11 | M29: 0.11
B30: HIGH | G30: 0.095 | H30: 0.095 | I30: 0.095 | J30: 0.095 | K30: 0.095 | L30: 0.095 | M30: 0.095
B32: Research and development (% of revenue)
B33: BASE | G33: 0.033 | H33: 0.033 | I33: 0.032 | J33: 0.032 | K33: 0.032 | L33: 0.032 | M33: 0.032
B34: LOW | G34: 0.015 | H34: 0.015 | I34: 0.015 | J34: 0.015 | K34: 0.015 | L34: 0.015 | M34: 0.015
B35: HIGH | G35: 0.008 | H35: 0.008 | I35: 0.008 | J35: 0.008 | K35: 0.008 | L35: 0.008 | M35: 0.008
B37: Other operating expenses (% of revenue)
B38: BASE | G38: 0.038 | H38: 0.038 | I38: 0.04 | J38: 0.04 | K38: 0.04 | L38: 0.04 | M38: 0.04
B39: LOW | G39: 0.015 | H39: 0.015 | I39: 0.015 | J39: 0.015 | K39: 0.015 | L39: 0.015 | M39: 0.015
B40: HIGH | G40: 0.008 | H40: 0.008 | I40: 0.008 | J40: 0.008 | K40: 0.008 | L40: 0.008 | M40: 0.008
B42: D&A (% of Beginning PPE)
B43: BASE | G43: 0.175 | H43: 0.175 | I43: 0.165 | J43: 0.165 | K43: 0.165 | L43: 0.165 | M43: 0.165
B44: LOW | G44: 0.148 | H44: 0.148 | I44: 0.148 | J44: 0.148 | K44: 0.148 | L44: 0.148 | M44: 0.148
B45: HIGH | G45: 0.14 | H45: 0.14 | I45: 0.14 | J45: 0.14 | K45: 0.14 | L45: 0.14 | M45: 0.14
B47: Tax rate (% of Earnings Before Tax)
B48: BASE | G48: 0.21 | H48: 0.21 | I48: 0.21 | J48: 0.21 | K48: 0.21 | L48: 0.21 | M48: 0.21
B49: LOW | G49: 0.21 | H49: 0.21 | I49: 0.21 | J49: 0.21 | K49: 0.21 | L49: 0.21 | M49: 0.21
B50: HIGH | G50: 0.21 | H50: 0.21 | I50: 0.21 | J50: 0.21 | K50: 0.21 | L50: 0.21 | M50: 0.21
B52: Balance Sheet Drivers
B53: Accounts Receivable (Days)
B54: BASE | G54: 106 | H54: 106 | I54: 106 | J54: 106 | K54: 106 | L54: 106 | M54: 106
B55: LOW | G55: 45 | H55: 45 | I55: 45 | J55: 45 | K55: 45 | L55: 45 | M55: 45
B56: HIGH | G56: 37 | H56: 37 | I56: 37 | J56: 37 | K56: 37 | L56: 37 | M56: 37
...

Sheet Input Data
B1: Group Financial Statements
B3: Income Statement | E3: 2021 | F3: =+E3+1 -> 2022 | G3: =+F3+1 -> 2023 | H3: =+G3+1 -> 2024 | I3: =+H3+1 -> 2025 | J3: TTM
B5: Sales and Revenues:
B6: Sales (Machinery, Energy & Transp./Power) | E6: 48188 | F6: 56574 | G6: 63869 | H6: 61363 | I6: 63980
B7: Revenues of Financial Products | E7: 2783 | F7: 2853 | G7: 3191 | H7: 3446 | I7: 3609
B8: Total Sales and Revenues | E8: 50971 | F8: 59427 | G8: 67060 | H8: 64809 | I8: 67589
B10: Operating Costs:
B11: Cost of goods sold | E11: 35513 | F11: 41350 | G11: 42767 | H11: 40199 | I11: 44752
B12: SG&A expenses | E12: 5365 | F12: 5651 | G12: 6371 | H12: 6667 | I12: 6985
B13: SG&A | E13: 3013 | F13: 3432 | G13: 4227 | H13: 4514 | I13: 4723
B14: D&A | E14: 2352 | F14: 2219 | G14: 2144 | H14: 2153 | I14: 2262
B15: R&D expenses | E15: 1686 | F15: 1814 | G15: 2108 | H15: 2107 | I15: 2148
B16: Interest expense of Financial Products | E16: 455 | F16: 565 | G16: 1030 | H16: 1286 | I16: 1359
B17: Goodwill impairment charge | E17: 0 | F17: 925 | G17: 0 | H17: 0 | I17: 0
B18: Other operating (income) expenses | E18: 1074 | F18: 1218 | G18: 1818 | H18: 1478 | I18: 1194
B19: Total Operating Costs | E19: 44093 | F19: 51523 | G19: 54094 | H19: 51737 | I19: 56438
B21: Operating Profit | E21: 6878 | F21: 7904 | G21: 12966 | H21: 13072 | I21: 11151
B23: Interest exp. (excl. Financial Products) | E23: 488 | F23: 443 | G23: 511 | H23: 512 | I23: 502
B24: Other income (expense) | E24: 1814 | F24: 1291 | G24: 595 | H24: 813 | I24: 892
... B33: Balance Sheet | E33: 2021 | F33: 2022 | G33: 2023 | H33: 2024 | I33: 2025
B35: Assets
B36: Cash and cash equivalents | E36: 9254 | F36: 7004 | G36: 6978 | H36: 6889 | I36: 9980
B37: Receivables – trade and other | E37: 8477 | F37: 8856 | G37: 9310 | H37: 9282 | I37: 10920
B38: Receivables – finance | E38: 8898 | F38: 9013 | G38: 9510 | H38: 9565 | I38: 10649
B39: Inventories | E39: 14038 | F39: 16270 | G39: 16565 | H39: 16827 | I39: 18135
B40: Other current assets | E40: 2788 | F40: 2642 | G40: 4586 | H40: 3119 | I40: 2801
B41: Total current assets | E41: 43455 | F41: 43785 | G41: 46949 | H41: 45682 | I41: 52485
B42: Property, plant and equipment – net | E42: 12090 | F42: 12028 | G42: 12680 | H42: 13361 | I42: 15140
B43: Long-term receivables (Trade & Fin.) | E43: 13911 | F43: 13278 | G43: 13902 | H43: 14467 | I43: 16414
B44: Goodwill & Intangible assets | E44: 7366 | F44: 6046 | G44: 5872 | H44: 5640 | I44: 5562
B45: Other non-current assets | E45: 5971 | F45: 6806 | G45: 8073 | H45: 8614 | I45: 8984
B46: Total assets | E46: 82793 | F46: 81943 | G46: 87476 | H46: 87764 | I46: 98585
B48: Liabilities
B49: Short-term borrowings | E49: 5404 | F49: 5957 | G49: 4643 | H49: 4393 | I49: 5514
B50: Accounts payable | E50: 8154 | F50: 8689 | G50: 7906 | H50: 7675 | I50: 8968
B51: Accrued expenses & wages | E51: 5999 | F51: 6393 | G51: 7715 | H51: 7634 | I51: 8141
B52: Long-term debt due within 1 yr | E52: 6352 | F52: 5322 | G52: 8763 | H52: 6665 | I52: 7120
B53: Other current liabilities | E53: 3938 | F53: 5170 | G53: 5701 | H53: 5905 | I53: 6815
B54: Total current liabilities | E54: 29847 | F54: 31531 | G54: 34728 | H54: 32272 | I54: 36558
B55: Long-term debt due after 1 yr | E55: 26033 | F55: 25714 | G55: 24472 | H55: 27351 | I55: 30696
...
